Workbook
Name Print_Area: UItvoering!$A$1:$H$198

Sheet Projectomschrijving
F1: versie 1 | G1: PL
A2: Projectnaam: | D2: Gemeente:
A3: Projectdatum start: | D3: =TODAY() -> 46086
A4: Projectdatum eind (verwacht):
A5: Betrokken projectleider: | D5: LL
D6: Project omschrijving
A44: Belanghebbende/ deelnemers (in-, extern)
A48: Contactpersoon 1: | C48: nvt
A49: Contactpersoon 2: | C49: nvt
H53: 1 van 1

Sheet Projectblad
A1: Project | B1: =Projectomschrijving!D2 -> Gemeente: | D1: =Projectomschrijving!D3 -> 46086 | F1: =$B$14 | H1: =Projectomschrijving!D5 -> LL
A2: (bestaand) | B2: Containernummer | E2: Betonputten
B3: =IF(A3>"","OOC……….","") | C3: Bouwjaar | E3: PUT | G3: Bouwjaar
B4: =IF(A4>"","OOC……….","") | E4: PUT
B5: =IF(A5>"","OOC……….","") | E5: PUT
B6: =IF(A6>"","OOC……….","") | E6: PUT
B7: =IF(A7>"","OOC……….","") | E7: PUT
A8: (nieuw) | B8: Containernummer | E8: Betonputten | G8: Vloer
B9: =IF(A9>"","OOC……….","") | C9: Bouwjaar | E9: PUT | G9: =IF(C9>"",C9,"") -> Bouwjaar
B10: =IF(A10>"","OOC……….","") | E10: PUT | G10: =IF(C10>"",C10,"")
B11: =IF(A11>"","OOC……….","") | E11: PUT | G11: =IF(C11>"",C11,"")
B12: =IF(A12>"","OOC……….","") | E12: PUT | G12: =IF(C12>"",C12,"")
B13: =IF(A13>"","OOC……….","") | E13: PUT | G13: =IF(C13>"",C13,"")
A14: Locatiecode | B14: =IF(B20="","",CONCATENATE("LOC",B20,F19)) | F14: Bezoekdatum: | G14: n.t.b.
A15: Maximale loopafstand: | F15: Aantal aansluitingen:
A16: Coordinaten (rijksdriehoek)
A17: Coördinaten (DD.dddddd°) | D17: ° | F17: °
A19: Straat | E19: Huisnr.
A20: Postcode | E20: Plaats
A21: Wijk
A23: Acties | B23: Tekening | C23: Nee | E23: Planning/week | F23: ~Keuze~ | G23: wk:
B24: Locatiefoto | C24: Ja | E24: Controle | F24: ~Keuze~
B25: KLIC | C25: Ja | E25: Resultaatfoto | F25: ~Keuze~
B26: Proefsleuf | C26: ~Keuze~
B27: Bestelling | C27: ~Keuze~ | E27: Ordernr: | F27: n.t.b.
B28: Ontvangst | C28: ~Keuze~
A29: Opmerkingen: | E29: Plaatsing mogelijk na proefsleuven: | H29: ~Keuze~
E30: Plaatsing definitief na (aanwijs)besluit: | H30: ~Keuze~
A31: Algemeen: | B31: =IF(NOT(ISBLANK(Projectomschrijving!$A$8)), Projectomschrijving!$A$8, "")
A33: Klic:
A35: Proefsleuf: | B35: =UItvoering!B40 -> 0
A37: Opdrachtgever: | B37: Grijs: | C37: In afwachting
B38: Groen: | C38: In afwachting
B39: Verkeer: | C39: In afwachting
B40: Inzameling: | C40: In afwachting
A42: Algemeen:
B52: IST | F52: SOLL
A67: Locatie foto: | F67: =$B$14
A93: Kaart:
A119: Bijzonderheden locatie:
...

Sheet Data
A1: ~Keuze~ | B1: ~Keuze~
A2: Ja | B2: Volgens Klic kabels en/of leidingen door het werkgebied
A3: Nee | B3: Volgens Klic nabij kabels en/of leidingen
A4: Misschien | B4: Volgens Klic geen kabels en/of leidingen door het werkgebied

Sheet UItvoering
A1: Project | B1: =[1]Projectomschrijving!D2 -> Gemeente: Maassluis | D1: 45348 | F1: =$B$14 -> LOC00 | H1: RBE
A2: (bestaand) | B2: Containernummer | E2: Betonputten
A3: =Projectblad!A3 -> 0 | C3: Bouwjaar | E3: PUT | G3: Bouwjaar
A4: =Projectblad!A4 -> 0 | E4: PUT
A5: =Projectblad!A5 -> 0 | E5: Put
A6: =Projectblad!A6 -> 0 | E6: =IF(A6>"",A6,"")
A7: =Projectblad!A7 -> 0 | E7: =IF(A7>"",A7,"")
E8: Betonputten | G8: Vloer
A9: =Projectblad!A9 -> 0 | E9: PUT | G9: =IF(C9>"",C9,"")
A10: =Projectblad!A10 -> 0 | E10: PUT | G10: =IF(C10>"",C10,"")
A11: =Projectblad!A11 -> 0 | E11: PUT | G11: =IF(C11>"",C11,"")
A12: =Projectblad!A12 -> 0 | B12: =IF(A12>"","OOC……….","") | E12: PUT | G12: =IF(C12>"",C12,"")
A13: =Projectblad!A13 -> 0 | B13: =IF(A13>"","OOC……….","") | E13: PUT | G13: =IF(C13>"",C13,"")
A14: Locatiecode | B14: =IF(B20="","",CONCATENATE("LOC",B20,F19)) -> LOC00 | F14: Bezoekdatum:
A15: Maximale loopafstand: | C15: =Projectblad!C15 -> 0 | F15: Aantal aansluitingen: | G15: =Projectblad!G15 -> 0
A16: Coordinaten (rijksdriehoek) | C16: =Projectblad!C16 -> 0 | E16: =Projectblad!E16 -> 0
A17: Coördinaten (DD.dddddd°) | C17: =Projectblad!C17 | E17: =Projectblad!E17
A19: Straat | B19: =Projectblad!B19 -> 0 | E19: Huisnr. | F19: =Projectblad!F19 -> 0
A20: Postcode | B20: =Projectblad!B20 -> 0 | E20: Plaats | F20: =Projectblad!F20 -> 0
A21: Wijk | B21: =Projectblad!B21 -> 0
A23: Acties | B23: Aanpassing straatwerk
B24: Aanpassing groen
B25: Aanpassing onder maaiveld
B27: Afzetting tijdens uitvoering
B28: Overig
A29: Opmerkingen: | E29: Plaatsing mogelijk na proefsleuven: | H29: ~Keuze~
E30: Plaatsing definitief na (aanwijs)besluit: | H30: ~Keuze~
A31: Algemeen: | B31: =Projectblad!B31
A36: Klic:
A40: Proefsleuf:
A67: Locatie foto: | F67: =$B$14 -> LOC00
A93: Klic
A119: Bijzonderheden locatie:
A133: Proefsleuf | F133: =$B$14 -> LOC00
A185: Bijzonderheden locatie:

Sheet Bestellijst
A2: Nieuw Renovatie | B2: Bouwjaar | C2: Datum plaatsing | D2: Aannemer Bammens Van der Hoeven | E2: Gemeente | F2: Straatnaam | G2: Huisnr. | H2: Postcode | I2: Datum bestelling | J2: Fractie | K2: Rest | L2: GFT | M2: Glas wit 1 comp. | N2: Glas bont 1 comp. | O2: Glas wit-bont 2 comp. | P2: Papier | Q2: Textiel | R2: Plastic | S2: Inhoud | T2: 060003 Betonput | U2: 1670 Console Nieuw | V2: 1650 Console Renovatie | W2: 449975 Putopvulling 680 mm | X2: Rand Ring | Y2: Datum levering | Z2: Order nr. Bammens | AA2: Type vloer | AB2: Leverancier | AC2: Kleur | AD2: Opnamesysteem | AE2: Toegang tot container | AF2: Status op locatie | AG2: Type OOC/BOC | AH2: Serienr. | AI2: Nieuw OOC NR. | AJ2: Oud BOC-OOC NR. | AK2: Unit ID | AL2: Locatie code
F14: Let op: gegevens invullen in projectblad
B16: Invullen door Bammens
B17: Invullen door aannemer

Sheet Meerwerkstaat
A1: Project:
E6: Eenheid | F6: Aantal | G6: Prijs per | H6: Totaal
B7: Meerwerkstaat | G7: eenheid | H7: Euro
H8: Ex BTW
B46: Totaal in Euro (ex Btw) | H46: =SUM(H9:H45) -> 0
A47: Projectleider Avalex
A48: Naam: R. Beset | E48: Naam:
E49: Datum:
A50: Akkoord: | E50: Akkoord:

Sheet Blad2
A1: Ophogen straatwerk (30x30)
A2: Verzetten banden
A3: Aanpassen bochtstraal
A4: Aanbrengen verlaagde band
A5: Aanleg tegelplateau
A6: Zetten opsluitbanden
A7: Aanbrengen tuinaarde- inzaaien
A8: Snoeiwerkzaamheden | I8: Bouwjaar
A9: Verplaatsen beplanting | I9: 2000
I10: 2001
A11: Verleggen kabel/ leiding | I11: 2002
A12: Verleggen Riool (PVC) | I12: 2003
A13: Aanbrengen extra verharding | I13: 2004
A14: Verzetten Kolk | I14: 2005
I15: 2006
I16: 2007
I17: 2008
I18: 2009
A19: Stremmen | I19: 2010
A20: Omleiden | I20: 2011
A21: Verkeersregelaar | I21: 2012
I22: 2013
I23: 2014
I24: 2015
A25: Ja | I25: 2016
A26: Nee | I26: 2017
A27: Ntb | I27: 2018
I28: 2019
I29: 2020
A30: Volgens orientatie-klic GEEN kabels en leidingen nabij locatie | I30: 2021
A31: Volgens orientatie-klic NABIJ kabels en leidingen nabij locatie | I31: 2022
A32: Volgens orientatie-klic kabels en leidingen op locatie AANWEZIG | I32: 2023
I33: 2024
A35: Volgens proefsleuf GEEN kabels en leidingen nabij locatie
A36: Volgens proefsleuf NABIJ kabels en leidingen nabij locatie
A37: Volgensproefsleuf kabels en leidingen op locatie AANWEZIG
A40: Behouden
A41: Vervangen
A42: Afvoeren
A43: Wisselen
...
